<?xml version="1.0"?>
<robot name="differential_drive__68__">
    <link name="differential_drive__68__">
        <inertial>
            <origin rpy="-3.141593 3.141593 -3.141593" xyz="0.000000 0.000000 0.000000" />
            <inertia iyz="0.0" iyy="0.0050208931788802" ixx="0.0062051238492131" izz="0.0095389438793063" ixz="0.0" ixy="0.0" />
            <mass value="2.0080223083496" />
        </inertial>
        <collision>
            <origin rpy="-3.141593 3.141593 -3.141593" xyz="0.000000 0.000000 0.000000" />
            <geometry>
                <box size="0.158000 0.179000 0.071000" />
            </geometry>
        </collision>
        <visual>
            <origin rpy="-3.141593 3.141593 0.000000" xyz="-0.000000 0.000000 0.035000" />
            <geometry>
                <mesh filename="file:///home/coppeliasim_simulation/urdf_from_coppelia/kinematic_model_Hokuyo_URG_04LX_UG01_body__70__.dae" />
            </geometry>
            <material name="Hokuyo_URG_04LX_UG01_body__70___material">
                <color rgba="1.000000 1.000000 0.111111 1.0" />
            </material>
        </visual>
    </link>
    <link name="wheel_right__75__">
        <inertial>
            <origin rpy="-3.141593 3.141593 -3.141593" xyz="0.000000 0.000000 0.000000" />
            <inertia iyz="0.0" iyy="3.2736381399445e-05" ixx="3.2736381399445e-05" izz="6.4412466599606e-05" ixz="0.0" ixy="0.0" />
            <mass value="0.063617251813412" />
        </inertial>
        <collision>
            <origin rpy="-3.141593 3.141593 -3.141593" xyz="0.000000 0.000000 0.000000" />
            <geometry>
                <cylinder length="0.0099999997764826" radius="0.045000001788139" />
            </geometry>
        </collision>
    </link>
    <joint type="continuous" name="joint_right__74__">
        <axis xyz="0 0 1" />
        <parent link="differential_drive__68__" />
        <child link="wheel_right__75__" />
        <origin rpy="-0.000000 1.571142 -0.000000" xyz="0.095000 -0.025000 -0.005000" />
    </joint>
    <link name="wheel_left__79__">
        <inertial>
            <origin rpy="-3.141593 3.141593 -3.141593" xyz="0.000000 0.000000 0.000000" />
            <inertia iyz="0.0" iyy="3.2736381399445e-05" ixx="3.2736381399445e-05" izz="6.4412466599606e-05" ixz="0.0" ixy="0.0" />
            <mass value="0.063617251813412" />
        </inertial>
        <collision>
            <origin rpy="-3.141593 3.141593 -3.141593" xyz="0.000000 0.000000 0.000000" />
            <geometry>
                <cylinder length="0.0099999997764826" radius="0.045000001788139" />
            </geometry>
        </collision>
    </link>
    <joint type="continuous" name="joint_left__78__">
        <axis xyz="0 0 1" />
        <parent link="differential_drive__68__" />
        <child link="wheel_left__79__" />
        <origin rpy="0.000000 1.570796 0.000000" xyz="-0.095000 -0.025000 -0.005000" />
    </joint>
</robot>
